<?xml version="1.0" ?>
<!-- =================================================================================== -->
<!-- |    This document was autogenerated by xacro from spesbot_description/urdf/spesbot.xacro | -->
<!-- |    EDITING THIS FILE BY HAND IS NOT RECOMMENDED                                 | -->
<!-- =================================================================================== -->
<robot name="spesbot">
  <link name="base_link">
    <visual>
      <geometry>
        <mesh filename="/home/milos/row-following/IsaacSimulation/meshes/mobile_base.stl"/>
      </geometry>
    </visual>
    <collision>
      <origin xyz="-0.15 0 0" rpy="0 0 0" />
      <geometry>
        <box size="0.4 0.3 0.02" />
      </geometry>
    </collision>
    <inertial>
      <mass value="5.0" />
      <origin xyz="0 0 0" rpy="0 0 0" />
      <inertia ixx="0.1" ixy="0" ixz="0" iyy="0.1" iyz="0" izz="0.1" />
    </inertial>
  </link>
  <joint name="left_motor" type="continuous">
    <parent link="base_link"/>
    <child link="left_wheel_link"/>
    <origin rpy="0 0 0" xyz="0 0.145 0"/>
    <axis xyz="0 1 0"/>
  </joint>
  <link name="left_wheel_link">
    <visual>
      <geometry>
        <mesh filename="/home/milos/row-following/IsaacSimulation/meshes/wheel.stl"/>
      </geometry>
    </visual>
    <collision>
      <origin xyz="0 0.03 0" rpy="1.5707 0 0" />
      <geometry>
        <cylinder radius="0.085" length="0.03"/>
      </geometry>
    </collision>
    <inertial>
      <mass value="2.0" />
      <origin xyz="0 0 0" rpy="0 0 0" />
      <inertia ixx="0.0001" ixy="0" ixz="0" iyy="0.0001" iyz="0" izz="0.0001" />
    </inertial>
  </link>
  <joint name="right_motor" type="continuous">
    <parent link="base_link"/>
    <child link="right_wheel_link"/>
    <origin rpy="0 0 0" xyz="0 -0.145 0"/>
    <axis xyz="0 1 0"/>
  </joint>
  <link name="right_wheel_link">
    <visual>
      <geometry>
        <mesh filename="/home/milos/row-following/IsaacSimulation/meshes/wheel.stl"/>
      </geometry>
      <origin rpy="0 0 3.14159" xyz="0 0 0"/>
    </visual>
    <collision>
      <origin xyz="0 -0.03 0" rpy="1.5707 0 0" />
      <geometry>
        <cylinder radius="0.085" length="0.03"/>
      </geometry>
    </collision>
    <inertial>
      <mass value="2.0" />
      <origin xyz="0 0 0" rpy="0 0 0" />
      <inertia ixx="0.0001" ixy="0" ixz="0" iyy="0.0001" iyz="0" izz="0.0001" />
    </inertial>
  </link>
  <joint name="caster_steering_joint" type="continuous">
    <parent link="base_link"/>
    <child link="caster_holder_link"/>
    <origin rpy="0 0 0" xyz="-0.31 0 0"/>
    <axis xyz="0 0 1"/>
  </joint>
  <link name="caster_holder_link">
    <visual>
      <geometry>
        <mesh filename="/home/milos/row-following/IsaacSimulation/meshes/caster_holder.stl"/>
      </geometry>
    </visual>
    <collision>
      <origin xyz="0 0 0" rpy="0 0 0" />
      <geometry>
        <cylinder radius="0.03" length="0.01"/>
      </geometry>
    </collision>
    <inertial>
      <mass value="0.3" />
      <origin xyz="0 0 0" rpy="0 0 0" />
      <inertia ixx="0.0001" ixy="0" ixz="0" iyy="0.0001" iyz="0" izz="0.0001" />
    </inertial>
  </link>
  <joint name="caster_wheel_joint" type="continuous">
    <parent link="caster_holder_link"/>
    <child link="caster_wheel_link"/>
    <origin rpy="0 0 0" xyz="-0.03 0 -0.05"/>
    <axis xyz="0 1 0"/>
  </joint>
  <link name="caster_wheel_link">
    <visual>
      <geometry>
        <mesh filename="/home/milos/row-following/IsaacSimulation/meshes/caster_wheel.stl"/>
      </geometry>
    </visual>
    <collision>
      <origin xyz="0 0 0" rpy="1.5707 0 0" />
      <geometry>
        <cylinder radius="0.033" length="0.03"/>
      </geometry>
    </collision>
    <inertial>
      <mass value="2.0" />
      <origin xyz="0 0 0" rpy="0 0 0" />
      <inertia ixx="0.0001" ixy="0" ixz="0" iyy="0.0001" iyz="0" izz="0.0001" />
    </inertial>
  </link>
  <!-- <link name="arm_base_link">
    <visual>
      <geometry>
        <mesh filename="/home/milos/row-following/IsaacSimulation/meshes/arm_base.stl"/>
      </geometry>
      <origin rpy="0 0 0" xyz="0 0 0"/>
    </visual>
  </link>
  <joint name="joint_1" type="revolute">
    <parent link="arm_base_link"/>
    <child link="arm_link_1"/>
    <origin rpy="0 0 0" xyz="0 0 0"/>
    <axis xyz="0 0 1"/>
    <limit effort="100" lower="-1.57" upper="1.57" velocity="0.5"/>
  </joint>
  <link name="arm_link_1">
    <visual>
      <geometry>
        <mesh filename="/home/milos/row-following/IsaacSimulation/meshes/arm_link_1.stl"/>
      </geometry>
      <origin rpy="0 0 0" xyz="0 0 0.01"/>
    </visual>
  </link>
  <joint name="joint_2" type="revolute">
    <parent link="arm_link_1"/>
    <child link="arm_link_2"/>
    <origin rpy="0 0 0" xyz="0.02 0 0.012"/>
    <axis xyz="0 1 0"/>
    <limit effort="100" lower="-1.57" upper="1.57" velocity="0.5"/>
  </joint>
  <link name="arm_link_2">
    <visual>
      <geometry>
        <mesh filename="/home/milos/row-following/IsaacSimulation/meshes/arm_link_2.stl"/>
      </geometry>
      <origin rpy="0 0 0" xyz="0 0 0"/>
    </visual>
  </link>
  <joint name="joint_3" type="revolute">
    <parent link="arm_link_2"/>
    <child link="arm_link_3"/>
    <origin rpy="0 0 0" xyz="0 0 0.1"/>
    <axis xyz="0 1 0"/>
    <limit effort="100" lower="-1.57" upper="1.57" velocity="0.5"/>
  </joint>
  <link name="arm_link_3">
    <visual>
      <geometry>
        <mesh filename="/home/milos/row-following/IsaacSimulation/meshes/arm_link_3.stl"/>
      </geometry>
      <origin rpy="0 0 0" xyz="0 0 0"/>
    </visual>
  </link>
  <joint name="joint_4" type="revolute">
    <parent link="arm_link_3"/>
    <child link="arm_link_4"/>
    <origin rpy="0 0 0" xyz="0.12 0 0"/>
    <axis xyz="0 1 0"/>
    <limit effort="100" lower="-1.57" upper="1.57" velocity="0.5"/>
  </joint>
  <link name="arm_link_4">
    <visual>
      <geometry>
        <mesh filename="/home/milos/row-following/IsaacSimulation/meshes/arm_link_4.stl"/>
      </geometry>
      <origin rpy="0 0 0" xyz="0 0 0"/>
    </visual>
  </link>
  <joint name="joint_5" type="revolute">
    <parent link="arm_link_4"/>
    <child link="arm_link_5"/>
    <origin rpy="0 0 0" xyz="0.04 0 0"/>
    <axis xyz="1 0 0"/>
    <limit effort="100" lower="-1.57" upper="1.57" velocity="0.5"/>
  </joint>
  <link name="arm_link_5">
    <visual>
      <geometry>
        <mesh filename="/home/milos/row-following/IsaacSimulation/meshes/gripper.stl"/>
      </geometry>
      <origin rpy="0 0 0" xyz="0 0 0"/>
    </visual>
  </link>
  <joint name="arm_tcp_joint" type="fixed">
    <parent link="arm_link_5"/>
    <child link="arm_tcp_link"/>
    <origin rpy="0 0 0" xyz="0.1 0 0"/>
  </joint>
  <link name="arm_tcp_link"/>
  <joint name="arm_fixed_joint" type="fixed">
    <parent link="base_link"/>
    <child link="arm_base_link"/>
    <origin rpy="0 0 0" xyz="0 0.08 0.08"/>
  </joint> -->
  <ros2_control name="fake_system" type="system">
    <hardware>
      <plugin>mock_components/GenericSystem</plugin>
    </hardware>
    <!-- <joint name="joint_1">
      <command_interface name="position"/>
      <state_interface name="position"/>
    </joint>
    <joint name="joint_2">
      <command_interface name="position"/>
      <state_interface name="position"/>
    </joint>
    <joint name="joint_3">
      <command_interface name="position"/>
      <state_interface name="position"/>
    </joint>
    <joint name="joint_4">
      <command_interface name="position"/>
      <state_interface name="position"/>
    </joint>
    <joint name="joint_5">
      <command_interface name="position"/>
      <state_interface name="position"/>
    </joint> -->
    <joint name="left_motor">
      <command_interface name="velocity"/>
      <state_interface name="position"/>
    </joint>
    <joint name="right_motor">
      <command_interface name="velocity"/>
      <state_interface name="position"/>
    </joint>
  </ros2_control>
</robot>
